<?xml version="1.0"?>
<robot name="simple_diff_drive">

  <link name="base_footprint"/>

  <link name="base_link">
    <visual>
      <geometry>
        <box size="0.3 0.2 0.1"/>
      </geometry>
      <material name="blue">
        <color rgba="0 0 1 1"/>
      </material>
    </visual>
    <collision>
      <geometry><box size="0.3 0.2 0.1"/></geometry>
    </collision>
    <inertial>
      <mass value="0.5"/>
      <origin xyz="0 0 0" rpy="0 0 0"/>
      <inertia ixx="0.00208" ixy="0" ixz="0" iyy="0.00416" iyz="0" izz="0.00541"/>
    </inertial>
  </link>

  <joint name="base_joint" type="fixed">
    <parent link="base_footprint"/>
    <child link="base_link"/>
    <origin xyz="0 0 0.1" rpy="0 0 0"/>
  </joint>

  <link name="left_wheel">
    <visual>
      <geometry>
        <cylinder radius="0.05" length="0.04"/>
      </geometry>
      <material name="black">
        <color rgba="0 0 0 1"/>
      </material>
    </visual>
    <collision>
      <geometry><cylinder radius="0.05" length="0.04"/></geometry>
    </collision>
    <inertial>
      <mass value="0.1" rpy="0 0 0"/>
      <inertia ixx="0.000075" ixy="0" ixz="0" iyy="0.000075" iyz="0" izz="0.000125"/>
    </inertial>
  </link>

  <joint name="left_wheel_joint" type="continuous">
    <parent link="base_link"/>
    <child link="left_wheel"/>
    <origin xyz="0 0.125 -0.05" rpy="-1.5708 0 0"/>
    <axis xyz="0 0 1"/>
  </joint>

  <link name="right_wheel">
    <visual>
      <geometry>
        <cylinder radius="0.05" length="0.04"/>
      </geometry>
      <material name="black"/>
    </visual>
    <collision>
      <geometry>
        <cylinder radius="0.05" length="0.04"/>
      </geometry>
    </collision>
  
    <inertial>
      <mass value="0.1"/>
      <origin xyz="0 0 0" rpy="0 0 0"/>
      <inertia ixx="0.000075" ixy="0" ixz="0" iyy="0.000075" iyz="0" izz="0.000125"/>
    </inertial>
  </link>

  <joint name="right_wheel_joint" type="continuous">
    <parent link="base_link"/>
    <child link="right_wheel"/>
    <origin xyz="0 -0.125 -0.05" rpy="1.5708 0 0"/>
    <axis xyz="0 0 1"/>
  </joint>

  <link name="caster_wheel">
    <visual>
      <geometry>
        <sphere radius="0.03"/>
      </geometry>
      <material name="grey">
        <color rgba="0.5 0.5 0.5 1"/>
      </material>
    </visual>
    <collision>
      <geometry>
        <sphere radius="0.03"/>
      </geometry>
    </collision>
    <inertial>
      <mass value="0.05"/> <inertia ixx="0.000018" ixy="0" ixz="0" iyy="0.000018" iyz="0" izz="0.000018"/>
    </inertial>
  </link>

  <joint name="caster_wheel_joint" type="fixed">
    <parent link="base_link"/>
    <child link="caster_wheel"/>
    <origin xyz="0.1 0 -0.07" rpy="0 0 0"/>
  </joint>

  <link name="laser_frame">
    <visual>
      <geometry>
        <cylinder radius="0.05" length="0.04"/>
      </geometry>
      <material name="red"><color rgba="1 0 0 1"/></material>
    </visual>
    <collision>
      <geometry>
        <cylinder radius="0.05" length="0.04"/>
      </geometry>
    </collision>
    <inertial>
      <mass value="0.1"/>
      <inertia ixx="0.000075" ixy="0" ixz="0" iyy="0.000075" iyz="0" izz="0.000125"/>
    </inertial>
  </link>

  <joint name="laser_joint" type="fixed">
    <parent link="base_link"/>
    <child link="laser_frame"/>
    <origin xyz="0.1 0 0.07" rpy="0 0 0"/>
  </joint>

  <gazebo reference="base_link">
    <material>Gazebo/Blue</material>
  </gazebo>
  
  <gazebo reference="left_wheel">
      <material>Gazebo/Black</material>
      <mu1 value="0.2"/> <mu2 value="0.2"/>
  </gazebo>
  
  <gazebo reference="right_wheel">
      <material>Gazebo/Black</material>
      <mu1 value="0.2"/> <mu2 value="0.2"/>
  </gazebo>
  
  <gazebo reference="caster_wheel">
      <material>Gazebo/Grey</material>
      <mu1 value="0.001"/> <mu2 value="0.001"/>
  </gazebo>

  <!-- <gazebo>
    <plugin
      name="ignition::gazebo::systems::DiffDrive"
      filename="libignition-gazebo-diff-drive-system.so">

      <left_joint>left_wheel_joint</left_joint>
      <right_joint>right_wheel_joint</right_joint>

      <wheel_separation>0.25</wheel_separation>
      <wheel_radius>0.05</wheel_radius>

      <max_wheel_torque>20</max_wheel_torque>
      <max_wheel_acceleration>1.0</max_wheel_acceleration>

      <odometry_frame>odom</odometry_frame>
      <robot_base_frame>base_footprint</robot_base_frame>

      <publish_odom>true</publish_odom>
      <publish_odom_tf>true</publish_odom_tf>
      <publish_wheel_tf>false</publish_wheel_tf>

    </plugin>
  </gazebo> -->

  <!-- Gazebo / Ignition diff drive plugin -->
  <gazebo>
    <plugin
      filename="ignition-gazebo-diff-drive-system"
      name="ignition::gazebo::systems::DiffDrive">

      <!-- Joints -->
      <left_joint>left_wheel_joint</left_joint>
      <right_joint>right_wheel_joint</right_joint>

      <!-- Kinematics -->
      <wheel_separation>0.25</wheel_separation>   <!-- meters -->
      <wheel_radius>0.05</wheel_radius>           <!-- meters -->

      <!-- Frames -->
      <frame_id>odom</frame_id>
      <child_frame_id>base_footprint</child_frame_id>

      <!-- Topics -->
      <topic>/cmd_vel</topic>
      <odom_topic>/model/my_robot/odometry</odom_topic>

      <!-- Behavior -->
      <update_rate>100</update_rate>
      <enable_odom>true</enable_odom>
      <publish_odom>true</publish_odom>
      <publish_tf>true</publish_tf>

    </plugin>
  </gazebo>


  <gazebo>
    <plugin
      filename="libignition-gazebo-sensors-system.so"
      name="ignition::gazebo::systems::Sensors"/>
  </gazebo>


  <!-- <gazebo reference="laser_frame">
    <sensor name="laser" type="gpu_lidar">
      <pose>0 0 0 0 0 0</pose>
      <update_rate>10</update_rate>
      <visualize>true</visualize>

      <lidar>
        <horizontal>
          <samples>360</samples>
          <min_angle>-3.14159</min_angle>
          <max_angle>3.14159</max_angle>
        </horizontal>
        <range>
          <min>0.3</min>
          <max>12.0</max>
          <resolution>0.01</resolution>
        </range>
      </lidar>
    </sensor>
  </gazebo> -->

  <gazebo reference="laser_frame">
  <sensor name="laser_sensor" type="gpu_lidar">
    <pose relative_to='laser_frame'>0 0 0 0 0 0</pose>
    <ignition_frame_id>laser_frame</ignition_frame_id>
    <topic>scan</topic>
    <update_rate>10</update_rate>

    <lidar>
      <scan>
        <horizontal>
          <samples>720</samples>
          <resolution>1</resolution>
          <min_angle>-1.5708</min_angle>
          <max_angle>1.5708</max_angle>
        </horizontal>
      </scan>

      <range>
        <min>0.05</min>
        <max>10.0</max>
        <resolution>0.01</resolution>
      </range>
    </lidar>

    <always_on>true</always_on>
    <visualize>true</visualize>
  </sensor>
</gazebo>


  <gazebo>
    <plugin filename="libignition-gazebo-joint-state-publisher-system.so"
            name="ignition::gazebo::systems::JointStatePublisher"/>
  </gazebo>

</robot>